Workbook
Name Frases: Principios!$B$22:$B$36
Name Frases_Fuente: Principios!$C$22:$C$36
Name Nombre: 'Configuración'!$B$4
Name Frecuencia: 'Configuración'!$B$5
Name Mes_Analisis: 'Configuración'!$B$7
Name Pct_Ahorro: 'Configuración'!$B$8
Name Pct_Deuda: 'Configuración'!$B$9
Name Pct_Vida: 'Configuración'!$B$10
Name Deuda_Fija: 'Configuración'!$B$11
Name Meses_Emergencia: 'Configuración'!$B$12
Name Lista_Categorias: 'Configuración'!$A$16:$A$35
Name Cat_Tipo: 'Configuración'!$B$16:$B$35
Name Cat_Presupuesto: 'Configuración'!$C$16:$C$35
Name Lista_Fuentes: 'Configuración'!$E$16:$E$25
Name Lista_TiposDeuda: 'Configuración'!$F$16:$F$25
Name Lista_Destinos: 'Configuración'!$G$16:$G$25
Name Lista_Metodos: 'Configuración'!$H$16:$H$25
Name Lista_Deudas: Deudas!$A$9:$A$23

Sheet Instrucciones
A1: PLANTILLA DE LIBERTAD FINANCIERA
A2: Controla tus gastos · Elimina tus deudas · Págate primero · Compra activos
B4: CÓMO USARLA
B5: 1. Configuración | C5: Escribe tu nombre, elige si controlarás tus gastos Diario, Semanal o Mensual y ajusta los porcentajes (por defecto la regla de Babilonia 10/20/70). Ajusta tus categorías y su presupuesto mensual.
B6: 2. Ingresos | C6: Registra cada ingreso: sueldo, ganancia de tu negocio, freelance o ingreso pasivo (rendimientos, rentas, dividendos).
B7: 3. Gastos | C7: Anota cada gasto el día que lo haces (o junta tus tickets y captúralos una vez por semana). Todo se resta automáticamente de tu ingreso.
B8: 4. Deudas | C8: Da de alta cada deuda con su saldo, tasa de interés ANUAL y pago mínimo. La plantilla las ordena sola: primero las que cobran intereses (tarjetas de crédito, la tasa más alta primero) y después los préstamos familiares sin intereses.
B9: 5. Abonos a Deudas | C9: Cada vez que pagues una deuda, regístralo aquí. El saldo de la deuda baja automáticamente.
B10: 6. Ahorro e Inversión | C10: Registra lo que te 'pagas primero': fondo de emergencia, inversiones, negocio, educación financiera. Si un activo te genera ingreso, regístralo en Ingresos como 'Ingreso pasivo'.
B11: 7. Resumen | C11: Tu tablero del mes: cuánto llevas gastado contra tu presupuesto del periodo, semáforo, avance del fondo de emergencia, índice de libertad financiera y fecha estimada para quedar libre de deudas.
B12: 8. Tendencia | C12: Tu evolución mes a mes durante el año.
B14: LEYENDA DE CELDAS
B15: Amarillo / texto azul | C15: Celdas que TÚ llenas (datos de entrada).
B16: Gris / texto negro | C16: Fórmulas automáticas. No las borres.
B17: Datos de ejemplo | C17: La plantilla trae datos de ejemplo de septiembre 2026 para que veas cómo funciona. Bórralos (solo las celdas amarillas) antes de empezar con tus datos.
B19: TIPS
B20: Fechas | C20: Escribe las fechas como dd/mm/aaaa. Las columnas 'Mes' y 'Semana' se calculan solas.
B21: Filas | C21: Gastos admite 1,000 registros; Ingresos, Abonos y Ahorro 300 cada uno; Deudas 15; Categorías 20.
B22: Mes a analizar | C22: Por defecto el Resumen muestra el mes actual. Para revisar otro mes, escribe cualquier fecha de ese mes en Configuración.

Sheet Resumen
A1: ="TABLERO DE LIBERTAD FINANCIERA · "&UPPER(TEXT(Mes_Analisis,"mmmm yyyy"))&IF(OR(Nombre="",Nombre="Tu nombre"),""," · "&Nombre)
A2: ="💬 “"&INDEX(Frases,MOD(DAY(TODAY())-1,ROWS(Frases))+1)&"” — "&INDEX(Frases_Fuente,MOD(DAY(TODAY())-1,ROWS(Frases))+1)
B5: Ingresos del mes | C5: Gastos de vida | D5: Abonos a deudas | E5: Ahorro e inversión | F5: Disponible | G5: Mensaje para ti
B6: =SUMIFS(Ingresos!$D$5:$D$304,Ingresos!$E$5:$E$304,Mes_Analisis) | C6: =SUMIFS(Gastos!$D$5:$D$1004,Gastos!$H$5:$H$1004,Mes_Analisis) | D6: =SUMIFS('Abonos a Deudas'!$C$5:$C$304,'Abonos a Deudas'!$E$5:$E$304,Mes_Analisis) | E6: =SUMIFS('Ahorro e Inversión'!$C$5:$C$304,'Ahorro e Inversión'!$E$5:$E$304,Mes_Analisis) | F6: =B6-C6-D6-E6 | G6: =IF(B6=0,"Registra tus ingresos del mes para empezar.",IF(F6<0,"⚠ Gastas más de lo que ganas. Controla tus gastos (2ª cura de Babilonia).",IF(E6<B6*Pct_Ahorro,"Aún no te pagas primero: aparta "&TEXT(B6*Pct_Ahorro-E6,"$#,##0")&" para tu bolsa.","¡Excelente! Te pagaste primero. Pon a trabajar tu oro.")))
B8: REGLA DE BABILONIA (10 / 20 / 70)
B9: Concepto | C9: % del ingreso | D9: Presupuesto | E9: Real | F9: Diferencia | G9: Estado
B10: Págate primero (ahorro e inversión) | C10: =Pct_Ahorro | D10: =$B$6*C10 | E10: =E6 | F10: =D10-E10 | G10: =IF(D10=0,"-",IF(E10>=D10,"✅ Meta cumplida","⏳ Faltan "&TEXT(D10-E10,"$#,##0")))
B11: Pago de deudas | C11: =Pct_Deuda | D11: =Deudas!$C$4 | E11: =D6 | F11: =D11-E11 | G11: =IF(D11=0,"-",IF(E11>=D11,"✅ Meta cumplida","⏳ Faltan "&TEXT(D11-E11,"$#,##0")))
B12: Gastos de vida | C12: =Pct_Vida | D12: =$B$6*C12 | E12: =C6 | F12: =D12-E12 | G12: =IF(D12=0,"-",IF(E12<=D12,"✅ Dentro del presupuesto","⚠ Excedido por "&TEXT(E12-D12,"$#,##0")))
B13: Total | C13: =SUM(C10:C12) | D13: =SUM(D10:D12) | E13: =SUM(E10:E12) | F13: =D13-E13
B15: CONTROL DE GASTO POR PERIODO | F15: INDICADORES PADRE RICO
B16: Frecuencia elegida | C16: =Frecuencia | F16: Tasa de ahorro del mes | G16: =IF(B6=0,0,E6/B6)
B17: Presupuesto de vida del mes | C17: =D12 | F17: Ingreso pasivo del mes (activos) | G17: =SUMIFS(Ingresos!$D$5:$D$304,Ingresos!$E$5:$E$304,Mes_Analisis,Ingresos!$B$5:$B$304,"Ingreso pasivo")
B18: Periodos en el mes | C18: =IF(Frecuencia="Diario",DAY(EOMONTH(Mes_Analisis,0)),IF(Frecuencia="Semanal",DAY(EOMONTH(Mes_Analisis,0))/7,1)) | F18: Índice de libertad financiera | G18: =IF(C6=0,0,G17/C6)
B19: Presupuesto por periodo | C19: =IF(C18=0,0,C17/C18) | F19: Fondo de emergencia acumulado | G19: =SUMIFS('Ahorro e Inversión'!$C$5:$C$304,'Ahorro e Inversión'!$B$5:$B$304,"Fondo de emergencia",'Ahorro e Inversión'!$A$5:$A$304,"<="&EOMONTH(Mes_Analisis,0))
B20: Periodo actual (hoy) | C20: =IF(Frecuencia="Diario",TEXT(TODAY(),"dd/mm/yyyy"),IF(Frecuencia="Semanal",TEXT(TODAY()-WEEKDAY(TODAY(),2)+1,"dd/mm")&" al "&TEXT(TODAY()-WEEKDAY(TODAY(),2)+7,"dd/mm"),TEXT(TODAY(),"mmmm yyyy"))) | F20: Meta del fondo de emergencia | G20: =Meses_Emergencia*MAX(C6,D12)
B21: Gastado en el periodo actual | C21: =IF(Frecuencia="Diario",SUMIFS(Gastos!$D$5:$D$1004,Gastos!$A$5:$A$1004,TODAY()),IF(Frecuencia="Semanal",SUMIFS(Gastos!$D$5:$D$1004,Gastos!$A$5:$A$1004,">="&(TODAY()-WEEKDAY(TODAY(),2)+1),Gastos!$A$5:$A$1004,"<="&(TODAY()-WEEKDAY(TODAY(),2)+7)),SUMIFS(Gastos!$D$5:$D$1004,Gastos!$H$5:$H$1004,DATE(YEAR(TODAY()),MONTH(TODAY()),1)))) | F21: Avance del fondo | G21: =IF(G20=0,0,MIN(1,G19/G20))
B22: Disponible en el periodo | C22: =C19-C21 | F22: Total invertido en activos | G22: =SUMIFS('Ahorro e Inversión'!$C$5:$C$304,'Ahorro e Inversión'!$A$5:$A$304,"<="&EOMONTH(Mes_Analisis,0))-G19
B23: Semáforo | C23: =IF(C19=0,"-",IF(C21<=C19*0.8,"🟢 Vas bien",IF(C21<=C19,"🟡 Cuidado, cerca del límite","🔴 Te pasaste: frena los deseos"))) | F23: Deuda total actual | G23: =Deudas!$G$24
F24: Deuda con intereses (prioridad) | G24: =SUMIFS(Deudas!$G$9:$G$23,Deudas!$D$9:$D$23,">0")
F25: Deuda sin intereses (familiar) | G25: =G23-G24
F26: Intereses que pagas al mes (estimado) | G26: =Deudas!$H$24
F27: Libre de deudas (estimado) | G27: =IF(G23=0,"¡Ya eres libre!",Deudas!$K$24)
F28: Índice de libertad = ingreso pasivo ÷ gastos de vida. Al llegar a 100% tus activos pagan tu vida.
B30: GASTOS POR CATEGORÍA DEL MES
B31: Categoría | C31: Tipo | D31: Presupuesto | E31: Real | F31: Disponible | G31: % usado
B32: =IF('Configuración'!A16="","",'Configuración'!A16) | C32: =IF(B32="","",'Configuración'!B16) | D32: =IF(B32="","",N('Configuración'!C16)) | E32: =IF(B32="","",SUMIFS(Gastos!$D$5:$D$1004,Gastos!$B$5:$B$1004,B32,Gastos!$H$5:$H$1004,Mes_Analisis)) | F32: =IF(B32="","",D32-E32) | G32: =IF(B32="","",IF(D32=0,IF(E32>0,1,0),E32/D32))
B33: =IF('Configuración'!A17="","",'Configuración'!A17) | C33: =IF(B33="","",'Configuración'!B17) | D33: =IF(B33="","",N('Configuración'!C17)) | E33: =IF(B33="","",SUMIFS(Gastos!$D$5:$D$1004,Gastos!$B$5:$B$1004,B33,Gastos!$H$5:$H$1004,Mes_Analisis)) | F33: =IF(B33="","",D33-E33) | G33: =IF(B33="","",IF(D33=0,IF(E33>0,1,0),E33/D33))
B34: =IF('Configuración'!A18="","",'Configuración'!A18) | C34: =IF(B34="","",'Configuración'!B18) | D34: =IF(B34="","",N('Configuración'!C18)) | E34: =IF(B34="","",SUMIFS(Gastos!$D$5:$D$1004,Gastos!$B$5:$B$1004,B34,Gastos!$H$5:$H$1004,Mes_Analisis)) | F34: =IF(B34="","",D34-E34) | G34: =IF(B34="","",IF(D34=0,IF(E34>0,1,0),E34/D34))
B35: =IF('Configuración'!A19="","",'Configuración'!A19) | C35: =IF(B35="","",'Configuración'!B19) | D35: =IF(B35="","",N('Configuración'!C19)) | E35: =IF(B35="","",SUMIFS(Gastos!$D$5:$D$1004,Gastos!$B$5:$B$1004,B35,Gastos!$H$5:$H$1004,Mes_Analisis)) | F35: =IF(B35="","",D35-E35) | G35: =IF(B35="","",IF(D35=0,IF(E35>0,1,0),E35/D35))
B36: =IF('Configuración'!A20="","",'Configuración'!A20) | C36: =IF(B36="","",'Configuración'!B20) | D36: =IF(B36="","",N('Configuración'!C20)) | E36: =IF(B36="","",SUMIFS(Gastos!$D$5:$D$1004,Gastos!$B$5:$B$1004,B36,Gastos!$H$5:$H$1004,Mes_Analisis)) | F36: =IF(B36="","",D36-E36) | G36: =IF(B36="","",IF(D36=0,IF(E36>0,1,0),E36/D36))
B37: =IF('Configuración'!A21="","",'Configuración'!A21) | C37: =IF(B37="","",'Configuración'!B21) | D37: =IF(B37="","",N('Configuración'!C21)) | E37: =IF(B37="","",SUMIFS(Gastos!$D$5:$D$1004,Gastos!$B$5:$B$1004,B37,Gastos!$H$5:$H$1004,Mes_Analisis)) | F37: =IF(B37="","",D37-E37) | G37: =IF(B37="","",IF(D37=0,IF(E37>0,1,0),E37/D37))
B38: =IF('Configuración'!A22="","",'Configuración'!A22) | C38: =IF(B38="","",'Configuración'!B22) | D38: =IF(B38="","",N('Configuración'!C22)) | E38: =IF(B38="","",SUMIFS(Gastos!$D$5:$D$1004,Gastos!$B$5:$B$1004,B38,Gastos!$H$5:$H$1004,Mes_Analisis)) | F38: =IF(B38="","",D38-E38) | G38: =IF(B38="","",IF(D38=0,IF(E38>0,1,0),E38/D38))
B39: =IF('Configuración'!A23="","",'Configuración'!A23) | C39: =IF(B39="","",'Configuración'!B23) | D39: =IF(B39="","",N('Configuración'!C23)) | E39: =IF(B39="","",SUMIFS(Gastos!$D$5:$D$1004,Gastos!$B$5:$B$1004,B39,Gastos!$H$5:$H$1004,Mes_Analisis)) | F39: =IF(B39="","",D39-E39) | G39: =IF(B39="","",IF(D39=0,IF(E39>0,1,0),E39/D39))
B40: =IF('Configuración'!A24="","",'Configuración'!A24) | C40: =IF(B40="","",'Configuración'!B24) | D40: =IF(B40="","",N('Configuración'!C24)) | E40: =IF(B40="","",SUMIFS(Gastos!$D$5:$D$1004,Gastos!$B$5:$B$1004,B40,Gastos!$H$5:$H$1004,Mes_Analisis)) | F40: =IF(B40="","",D40-E40) | G40: =IF(B40="","",IF(D40=0,IF(E40>0,1,0),E40/D40))
B41: =IF('Configuración'!A25="","",'Configuración'!A25) | C41: =IF(B41="","",'Configuración'!B25) | D41: =IF(B41="","",N('Configuración'!C25)) | E41: =IF(B41="","",SUMIFS(Gastos!$D$5:$D$1004,Gastos!$B$5:$B$1004,B41,Gastos!$H$5:$H$1004,Mes_Analisis)) | F41: =IF(B41="","",D41-E41) | G41: =IF(B41="","",IF(D41=0,IF(E41>0,1,0),E41/D41))
B42: =IF('Configuración'!A26="","",'Configuración'!A26) | C42: =IF(B42="","",'Configuración'!B26) | D42: =IF(B42="","",N('Configuración'!C26)) | E42: =IF(B42="","",SUMIFS(Gastos!$D$5:$D$1004,Gastos!$B$5:$B$1004,B42,Gastos!$H$5:$H$1004,Mes_Analisis)) | F42: =IF(B42="","",D42-E42) | G42: =IF(B42="","",IF(D42=0,IF(E42>0,1,0),E42/D42))
B43: =IF('Configuración'!A27="","",'Configuración'!A27) | C43: =IF(B43="","",'Configuración'!B27) | D43: =IF(B43="","",N('Configuración'!C27)) | E43: =IF(B43="","",SUMIFS(Gastos!$D$5:$D$1004,Gastos!$B$5:$B$1004,B43,Gastos!$H$5:$H$1004,Mes_Analisis)) | F43: =IF(B43="","",D43-E43) | G43: =IF(B43="","",IF(D43=0,IF(E43>0,1,0),E43/D43))
... B51: =IF('Configuración'!A35="","",'Configuración'!A35) | C51: =IF(B51="","",'Configuración'!B35) | D51: =IF(B51="","",N('Configuración'!C35)) | E51: =IF(B51="","",SUMIFS(Gastos!$D$5:$D$1004,Gastos!$B$5:$B$1004,B51,Gastos!$H$5:$H$1004,Mes_Analisis)) | F51: =IF(B51="","",D51-E51) | G51: =IF(B51="","",IF(D51=0,IF(E51>0,1,0),E51/D51))
B52: Total | D52: =SUM(D32:D51) | E52: =SUM(E32:E51) | F52: =D52-E52 | G52: =IF(D52=0,0,E52/D52)
...

Sheet Configuración
A1: CONFIGURACIÓN
A2: Llena solo las celdas amarillas
A4: Tu nombre | B4: Tu nombre
A5: Frecuencia de control de gastos | B5: Semanal
A6: Mes a analizar (opcional, vacío = mes actual)
A7: Mes en análisis (automático) | B7: =IF(B6="",DATE(YEAR(TODAY()),MONTH(TODAY()),1),DATE(YEAR(B6),MONTH(B6),1))
A8: % Págate primero (ahorro e inversión) | B8: 0.1 | C8: Regla de Babilonia: 10%
A9: % Pago de deudas | B9: 0.2 | C9: Regla de Babilonia: 20%
A10: % Gastos de vida (automático) | B10: =1-B8-B9 | C10: =IF(B10<0,"⚠ Los % suman más de 100%","Regla de Babilonia: 70%")
A11: Presupuesto fijo mensual para deudas (opcional) | C11: Si lo dejas vacío se usa el % de deudas × ingreso del mes
A12: Meta del fondo de emergencia (meses de gastos) | B12: 3
A15: Categoría de gasto | B15: Tipo | C15: Presupuesto mensual | E15: Fuentes de ingreso | F15: Tipos de deuda | G15: Destinos de ahorro | H15: Métodos de pago | I15: Frecuencias
A16: Vivienda / Renta | B16: Necesidad | C16: 6500 | E16: Sueldo | F16: Tarjeta de crédito | G16: Fondo de emergencia | H16: Efectivo | I16: Diario
A17: Servicios (luz, agua, gas) | B17: Necesidad | C17: 900 | E17: Negocio | F17: Préstamo personal | G17: Inversión (bolsa, CETES, fondos) | H17: Débito | I17: Semanal
A18: Súper / Despensa | B18: Necesidad | C18: 3800 | E18: Freelance / Extra | F18: Crédito auto | G18: Negocio | H18: Transferencia | I18: Mensual
A19: Transporte / Gasolina | B19: Necesidad | C19: 1800 | E19: Ingreso pasivo | F19: Crédito hipotecario | G19: Bienes raíces | H19: Tarjeta de crédito
A20: Teléfono / Internet | B20: Necesidad | C20: 650 | E20: Otro | F20: Préstamo familiar | G20: Educación financiera
A21: Salud / Farmacia | B21: Necesidad | C21: 500 | F21: Préstamo amigo | G21: Retiro / Afore
A22: Educación | B22: Necesidad | C22: 400 | F22: Otro | G22: Otro
A23: Mascotas | B23: Necesidad | C23: 300
A24: Comida fuera / Antojos | B24: Deseo | C24: 1200
A25: Entretenimiento | B25: Deseo | C25: 600
A26: Ropa / Calzado | B26: Deseo | C26: 500
A27: Suscripciones | B27: Deseo | C27: 350 | E27: Puedes agregar opciones en las celdas amarillas vacías de cada lista.
A28: Regalos | B28: Deseo | C28: 300
A29: Otros | B29: Deseo | C29: 400
A36: Total presupuesto de categorías | C36: =SUM(C16:C35)

Sheet Ingresos
A1: INGRESOS
A2: Sueldo, ganancias del negocio e ingreso pasivo. Todo lo que entra a tu bolsa.
A4: Fecha | B4: Fuente | C4: Descripción | D4: Monto | E4: Mes | F4: ¿Trabajo o activo?
A5: 46266 | B5: Sueldo | C5: Quincena 1 | D5: 11500 | E5: =IF(A5="","",DATE(YEAR(A5),MONTH(A5),1)) | F5: =IF(B5="","",IF(B5="Ingreso pasivo","Activo (pasivo)","Trabajo (activo)"))
A6: 46275 | B6: Ingreso pasivo | C6: Rendimiento CETES | D6: 280 | E6: =IF(A6="","",DATE(YEAR(A6),MONTH(A6),1)) | F6: =IF(B6="","",IF(B6="Ingreso pasivo","Activo (pasivo)","Trabajo (activo)"))
A7: 46280 | B7: Sueldo | C7: Quincena 2 | D7: 11500 | E7: =IF(A7="","",DATE(YEAR(A7),MONTH(A7),1)) | F7: =IF(B7="","",IF(B7="Ingreso pasivo","Activo (pasivo)","Trabajo (activo)"))
A8: 46285 | B8: Negocio | C8: Venta de postres | D8: 3400 | E8: =IF(A8="","",DATE(YEAR(A8),MONTH(A8),1)) | F8: =IF(B8="","",IF(B8="Ingreso pasivo","Activo (pasivo)","Trabajo (activo)"))
E9: =IF(A9="","",DATE(YEAR(A9),MONTH(A9),1)) | F9: =IF(B9="","",IF(B9="Ingreso pasivo","Activo (pasivo)","Trabajo (activo)"))
E10: =IF(A10="","",DATE(YEAR(A10),MONTH(A10),1)) | F10: =IF(B10="","",IF(B10="Ingreso pasivo","Activo (pasivo)","Trabajo (activo)"))
E11: =IF(A11="","",DATE(YEAR(A11),MONTH(A11),1)) | F11: =IF(B11="","",IF(B11="Ingreso pasivo","Activo (pasivo)","Trabajo (activo)"))
E12: =IF(A12="","",DATE(YEAR(A12),MONTH(A12),1)) | F12: =IF(B12="","",IF(B12="Ingreso pasivo","Activo (pasivo)","Trabajo (activo)"))
E13: =IF(A13="","",DATE(YEAR(A13),MONTH(A13),1)) | F13: =IF(B13="","",IF(B13="Ingreso pasivo","Activo (pasivo)","Trabajo (activo)"))
E14: =IF(A14="","",DATE(YEAR(A14),MONTH(A14),1)) | F14: =IF(B14="","",IF(B14="Ingreso pasivo","Activo (pasivo)","Trabajo (activo)"))
E15: =IF(A15="","",DATE(YEAR(A15),MONTH(A15),1)) | F15: =IF(B15="","",IF(B15="Ingreso pasivo","Activo (pasivo)","Trabajo (activo)"))
E16: =IF(A16="","",DATE(YEAR(A16),MONTH(A16),1)) | F16: =IF(B16="","",IF(B16="Ingreso pasivo","Activo (pasivo)","Trabajo (activo)"))
E17: =IF(A17="","",DATE(YEAR(A17),MONTH(A17),1)) | F17: =IF(B17="","",IF(B17="Ingreso pasivo","Activo (pasivo)","Trabajo (activo)"))
E18: =IF(A18="","",DATE(YEAR(A18),MONTH(A18),1)) | F18: =IF(B18="","",IF(B18="Ingreso pasivo","Activo (pasivo)","Trabajo (activo)"))
E19: =IF(A19="","",DATE(YEAR(A19),MONTH(A19),1)) | F19: =IF(B19="","",IF(B19="Ingreso pasivo","Activo (pasivo)","Trabajo (activo)"))
E20: =IF(A20="","",DATE(YEAR(A20),MONTH(A20),1)) | F20: =IF(B20="","",IF(B20="Ingreso pasivo","Activo (pasivo)","Trabajo (activo)"))
... E304: =IF(A304="","",DATE(YEAR(A304),MONTH(A304),1)) | F304: =IF(B304="","",IF(B304="Ingreso pasivo","Activo (pasivo)","Trabajo (activo)"))

Sheet Gastos
A1: REGISTRO DE GASTOS
A2: Anota cada gasto diario o semanal. 'Controla tus gastos' — 2ª cura de Babilonia.
A4: Fecha | B4: Categoría | C4: Descripción | D4: Monto | E4: Método de pago | F4: Necesidad / Deseo | G4: Semana | H4: Mes | J4: Nota
A5: 46266 | B5: Vivienda / Renta | C5: Renta septiembre | D5: 6500 | E5: Transferencia | F5: =IF(B5="","",IFERROR(INDEX(Cat_Tipo,MATCH(B5,Lista_Categorias,0)),"Deseo")) | G5: =IF(A5="","",WEEKNUM(A5,2)) | H5: =IF(A5="","",DATE(YEAR(A5),MONTH(A5),1)) | J5: Los gastos con tarjeta de crédito aparecen en rojo: si no liquidas el total, se convierten en deuda con intereses.
A6: 46267 | B6: Súper / Despensa | C6: Despensa semanal | D6: 920 | E6: Débito | F6: =IF(B6="","",IFERROR(INDEX(Cat_Tipo,MATCH(B6,Lista_Categorias,0)),"Deseo")) | G6: =IF(A6="","",WEEKNUM(A6,2)) | H6: =IF(A6="","",DATE(YEAR(A6),MONTH(A6),1))
A7: 46268 | B7: Transporte / Gasolina | C7: Gasolina | D7: 600 | E7: Débito | F7: =IF(B7="","",IFERROR(INDEX(Cat_Tipo,MATCH(B7,Lista_Categorias,0)),"Deseo")) | G7: =IF(A7="","",WEEKNUM(A7,2)) | H7: =IF(A7="","",DATE(YEAR(A7),MONTH(A7),1))
A8: 46270 | B8: Comida fuera / Antojos | C8: Café y pan | D8: 95 | E8: Efectivo | F8: =IF(B8="","",IFERROR(INDEX(Cat_Tipo,MATCH(B8,Lista_Categorias,0)),"Deseo")) | G8: =IF(A8="","",WEEKNUM(A8,2)) | H8: =IF(A8="","",DATE(YEAR(A8),MONTH(A8),1))
A9: 46271 | B9: Servicios (luz, agua, gas) | C9: Recibo de luz | D9: 480 | E9: Transferencia | F9: =IF(B9="","",IFERROR(INDEX(Cat_Tipo,MATCH(B9,Lista_Categorias,0)),"Deseo")) | G9: =IF(A9="","",WEEKNUM(A9,2)) | H9: =IF(A9="","",DATE(YEAR(A9),MONTH(A9),1))
A10: 46273 | B10: Teléfono / Internet | C10: Internet casa | D10: 499 | E10: Débito | F10: =IF(B10="","",IFERROR(INDEX(Cat_Tipo,MATCH(B10,Lista_Categorias,0)),"Deseo")) | G10: =IF(A10="","",WEEKNUM(A10,2)) | H10: =IF(A10="","",DATE(YEAR(A10),MONTH(A10),1))
A11: 46274 | B11: Súper / Despensa | C11: Despensa semanal | D11: 875 | E11: Débito | F11: =IF(B11="","",IFERROR(INDEX(Cat_Tipo,MATCH(B11,Lista_Categorias,0)),"Deseo")) | G11: =IF(A11="","",WEEKNUM(A11,2)) | H11: =IF(A11="","",DATE(YEAR(A11),MONTH(A11),1))
A12: 46277 | B12: Entretenimiento | C12: Cine | D12: 260 | E12: Tarjeta de crédito | F12: =IF(B12="","",IFERROR(INDEX(Cat_Tipo,MATCH(B12,Lista_Categorias,0)),"Deseo")) | G12: =IF(A12="","",WEEKNUM(A12,2)) | H12: =IF(A12="","",DATE(YEAR(A12),MONTH(A12),1))
A13: 46279 | B13: Salud / Farmacia | C13: Medicamento | D13: 185 | E13: Efectivo | F13: =IF(B13="","",IFERROR(INDEX(Cat_Tipo,MATCH(B13,Lista_Categorias,0)),"Deseo")) | G13: =IF(A13="","",WEEKNUM(A13,2)) | H13: =IF(A13="","",DATE(YEAR(A13),MONTH(A13),1))
A14: 46281 | B14: Súper / Despensa | C14: Despensa semanal | D14: 910 | E14: Débito | F14: =IF(B14="","",IFERROR(INDEX(Cat_Tipo,MATCH(B14,Lista_Categorias,0)),"Deseo")) | G14: =IF(A14="","",WEEKNUM(A14,2)) | H14: =IF(A14="","",DATE(YEAR(A14),MONTH(A14),1))
A15: 46283 | B15: Suscripciones | C15: Streaming | D15: 219 | E15: Tarjeta de crédito | F15: =IF(B15="","",IFERROR(INDEX(Cat_Tipo,MATCH(B15,Lista_Categorias,0)),"Deseo")) | G15: =IF(A15="","",WEEKNUM(A15,2)) | H15: =IF(A15="","",DATE(YEAR(A15),MONTH(A15),1))
A16: 46285 | B16: Comida fuera / Antojos | C16: Comida familiar | D16: 540 | E16: Efectivo | F16: =IF(B16="","",IFERROR(INDEX(Cat_Tipo,MATCH(B16,Lista_Categorias,0)),"Deseo")) | G16: =IF(A16="","",WEEKNUM(A16,2)) | H16: =IF(A16="","",DATE(YEAR(A16),MONTH(A16),1))
A17: 46286 | B17: Transporte / Gasolina | C17: Gasolina | D17: 600 | E17: Débito | F17: =IF(B17="","",IFERROR(INDEX(Cat_Tipo,MATCH(B17,Lista_Categorias,0)),"Deseo")) | G17: =IF(A17="","",WEEKNUM(A17,2)) | H17: =IF(A17="","",DATE(YEAR(A17),MONTH(A17),1))
A18: 46288 | B18: Súper / Despensa | C18: Despensa semanal | D18: 890 | E18: Débito | F18: =IF(B18="","",IFERROR(INDEX(Cat_Tipo,MATCH(B18,Lista_Categorias,0)),"Deseo")) | G18: =IF(A18="","",WEEKNUM(A18,2)) | H18: =IF(A18="","",DATE(YEAR(A18),MONTH(A18),1))
F19: =IF(B19="","",IFERROR(INDEX(Cat_Tipo,MATCH(B19,Lista_Categorias,0)),"Deseo")) | G19: =IF(A19="","",WEEKNUM(A19,2)) | H19: =IF(A19="","",DATE(YEAR(A19),MONTH(A19),1))
F20: =IF(B20="","",IFERROR(INDEX(Cat_Tipo,MATCH(B20,Lista_Categorias,0)),"Deseo")) | G20: =IF(A20="","",WEEKNUM(A20,2)) | H20: =IF(A20="","",DATE(YEAR(A20),MONTH(A20),1))
F21: =IF(B21="","",IFERROR(INDEX(Cat_Tipo,MATCH(B21,Lista_Categorias,0)),"Deseo")) | G21: =IF(A21="","",WEEKNUM(A21,2)) | H21: =IF(A21="","",DATE(YEAR(A21),MONTH(A21),1))
F22: =IF(B22="","",IFERROR(INDEX(Cat_Tipo,MATCH(B22,Lista_Categorias,0)),"Deseo")) | G22: =IF(A22="","",WEEKNUM(A22,2)) | H22: =IF(A22="","",DATE(YEAR(A22),MONTH(A22),1))
F23: =IF(B23="","",IFERROR(INDEX(Cat_Tipo,MATCH(B23,Lista_Categorias,0)),"Deseo")) | G23: =IF(A23="","",WEEKNUM(A23,2)) | H23: =IF(A23="","",DATE(YEAR(A23),MONTH(A23),1))
F24: =IF(B24="","",IFERROR(INDEX(Cat_Tipo,MATCH(B24,Lista_Categorias,0)),"Deseo")) | G24: =IF(A24="","",WEEKNUM(A24,2)) | H24: =IF(A24="","",DATE(YEAR(A24),MONTH(A24),1))
F25: =IF(B25="","",IFERROR(INDEX(Cat_Tipo,MATCH(B25,Lista_Categorias,0)),"Deseo")) | G25: =IF(A25="","",WEEKNUM(A25,2)) | H25: =IF(A25="","",DATE(YEAR(A25),MONTH(A25),1))
F26: =IF(B26="","",IFERROR(INDEX(Cat_Tipo,MATCH(B26,Lista_Categorias,0)),"Deseo")) | G26: =IF(A26="","",WEEKNUM(A26,2)) | H26: =IF(A26="","",DATE(YEAR(A26),MONTH(A26),1))
F27: =IF(B27="","",IFERROR(INDEX(Cat_Tipo,MATCH(B27,Lista_Categorias,0)),"Deseo")) | G27: =IF(A27="","",WEEKNUM(A27,2)) | H27: =IF(A27="","",DATE(YEAR(A27),MONTH(A27),1))
F28: =IF(B28="","",IFERROR(INDEX(Cat_Tipo,MATCH(B28,Lista_Categorias,0)),"Deseo")) | G28: =IF(A28="","",WEEKNUM(A28,2)) | H28: =IF(A28="","",DATE(YEAR(A28),MONTH(A28),1))
F29: =IF(B29="","",IFERROR(INDEX(Cat_Tipo,MATCH(B29,Lista_Categorias,0)),"Deseo")) | G29: =IF(A29="","",WEEKNUM(A29,2)) | H29: =IF(A29="","",DATE(YEAR(A29),MONTH(A29),1))
F30: =IF(B30="","",IFERROR(INDEX(Cat_Tipo,MATCH(B30,Lista_Categorias,0)),"Deseo")) | G30: =IF(A30="","",WEEKNUM(A30,2)) | H30: =IF(A30="","",DATE(YEAR(A30),MONTH(A30),1))
... F1004: =IF(B1004="","",IFERROR(INDEX(Cat_Tipo,MATCH(B1004,Lista_Categorias,0)),"Deseo")) | G1004: =IF(A1004="","",WEEKNUM(A1004,2)) | H1004: =IF(A1004="","",DATE(YEAR(A1004),MONTH(A1004),1))

Sheet Deudas
A1: PLAN PARA ELIMINAR DEUDAS
A2: Prioridad 1: deudas con intereses (tasa más alta primero). Prioridad 2: préstamos familiares sin intereses (saldo más pequeño primero).
A4: Presupuesto del mes para deudas | C4: =IF(Deuda_Fija<>"",Deuda_Fija,Resumen!$B$6*Pct_Deuda) | E4: =IF(C4<C5,"⚠ Tu presupuesto no alcanza para los pagos mínimos. Recorta tus gastos tipo Deseo o aumenta tus ingresos.",IF(C6>0,"✔ Aplica el extra de "&TEXT(C6,"$#,##0")&" a la deuda con prioridad 1: así ahorras más intereses.","✔ Cubres tus mínimos."))
A5: Suma de pagos mínimos | C5: =SUM(O9:O23)
A6: Dinero extra para la deuda prioritaria | C6: =MAX(0,C4-C5)
A8: Deuda | B8: Tipo | C8: Saldo inicial | D8: Tasa anual | E8: Pago mínimo mensual | F8: Abonos realizados | G8: Saldo actual | H8: Interés mensual estimado | I8: Prioridad | J8: Pago sugerido este mes | K8: Meses para liquidar | L8: Fecha estimada libre | M8: Estrategia | N8: Puntaje | O8: Mínimo aplicable | P8: Remanente
A9: TDC Banco Azul | B9: Tarjeta de crédito | C9: 18500 | D9: 0.62 | E9: 1200 | F9: =IF(A9="",0,SUMIF('Abonos a Deudas'!$B$5:$B$304,A9,'Abonos a Deudas'!$C$5:$C$304)) | G9: =IF(A9="","",MAX(0,C9-F9)) | H9: =IF(A9="","",G9*D9/12) | I9: =IF(OR(A9="",N(G9)<=0),"",COUNTIF($N$9:$N$23,">"&N9)+COUNTIF($N$9:N9,N9)) | J9: =IF(I9="",0,O9+MIN(P9,MAX(0,$C$6-SUMIF($I$9:$I$23,"<"&I9,$P$9:$P$23)))) | K9: =IF(A9="","",IF(N(G9)<=0,0,IF(J9<=0,"Después de las anteriores",IF(D9=0,ROUNDUP(G9/J9,0),IF(J9<=H9,"Nunca: pago < interés",ROUNDUP(NPER(D9/12,-J9,G9),0)))))) | L9: =IF(ISNUMBER(K9),EDATE(Mes_Analisis,K9),"") | M9: =IF(A9="","",IF(N(G9)<=0,"✅ ¡Liquidada! Celébralo",IF(I9=1,"🎯 Ataca aquí: todo el dinero extra",IF(D9>0,"Paga el mínimo: genera intereses","Sin intereses: en segundo plano")))) | N9: =IF(A9="","",IF(G9<=0,-1,IF(D9>0,1+D9,1/(1+G9)))) | O9: =IF(OR(A9="",N(G9)<=0),0,MIN(G9,E9)) | P9: =IF(OR(A9="",N(G9)<=0),0,G9-O9)
A10: TDC Tienda departamental | B10: Tarjeta de crédito | C10: 6200 | D10: 0.85 | E10: 650 | F10: =IF(A10="",0,SUMIF('Abonos a Deudas'!$B$5:$B$304,A10,'Abonos a Deudas'!$C$5:$C$304)) | G10: =IF(A10="","",MAX(0,C10-F10)) | H10: =IF(A10="","",G10*D10/12) | I10: =IF(OR(A10="",N(G10)<=0),"",COUNTIF($N$9:$N$23,">"&N10)+COUNTIF($N$9:N10,N10)) | J10: =IF(I10="",0,O10+MIN(P10,MAX(0,$C$6-SUMIF($I$9:$I$23,"<"&I10,$P$9:$P$23)))) | K10: =IF(A10="","",IF(N(G10)<=0,0,IF(J10<=0,"Después de las anteriores",IF(D10=0,ROUNDUP(G10/J10,0),IF(J10<=H10,"Nunca: pago < interés",ROUNDUP(NPER(D10/12,-J10,G10),0)))))) | L10: =IF(ISNUMBER(K10),EDATE(Mes_Analisis,K10),"") | M10: =IF(A10="","",IF(N(G10)<=0,"✅ ¡Liquidada! Celébralo",IF(I10=1,"🎯 Ataca aquí: todo el dinero extra",IF(D10>0,"Paga el mínimo: genera intereses","Sin intereses: en segundo plano")))) | N10: =IF(A10="","",IF(G10<=0,-1,IF(D10>0,1+D10,1/(1+G10)))) | O10: =IF(OR(A10="",N(G10)<=0),0,MIN(G10,E10)) | P10: =IF(OR(A10="",N(G10)<=0),0,G10-O10)
A11: Préstamo personal | B11: Préstamo personal | C11: 25000 | D11: 0.28 | E11: 1500 | F11: =IF(A11="",0,SUMIF('Abonos a Deudas'!$B$5:$B$304,A11,'Abonos a Deudas'!$C$5:$C$304)) | G11: =IF(A11="","",MAX(0,C11-F11)) | H11: =IF(A11="","",G11*D11/12) | I11: =IF(OR(A11="",N(G11)<=0),"",COUNTIF($N$9:$N$23,">"&N11)+COUNTIF($N$9:N11,N11)) | J11: =IF(I11="",0,O11+MIN(P11,MAX(0,$C$6-SUMIF($I$9:$I$23,"<"&I11,$P$9:$P$23)))) | K11: =IF(A11="","",IF(N(G11)<=0,0,IF(J11<=0,"Después de las anteriores",IF(D11=0,ROUNDUP(G11/J11,0),IF(J11<=H11,"Nunca: pago < interés",ROUNDUP(NPER(D11/12,-J11,G11),0)))))) | L11: =IF(ISNUMBER(K11),EDATE(Mes_Analisis,K11),"") | M11: =IF(A11="","",IF(N(G11)<=0,"✅ ¡Liquidada! Celébralo",IF(I11=1,"🎯 Ataca aquí: todo el dinero extra",IF(D11>0,"Paga el mínimo: genera intereses","Sin intereses: en segundo plano")))) | N11: =IF(A11="","",IF(G11<=0,-1,IF(D11>0,1+D11,1/(1+G11)))) | O11: =IF(OR(A11="",N(G11)<=0),0,MIN(G11,E11)) | P11: =IF(OR(A11="",N(G11)<=0),0,G11-O11)
A12: Préstamo mamá | B12: Préstamo familiar | C12: 10000 | D12: 0 | E12: 0 | F12: =IF(A12="",0,SUMIF('Abonos a Deudas'!$B$5:$B$304,A12,'Abonos a Deudas'!$C$5:$C$304)) | G12: =IF(A12="","",MAX(0,C12-F12)) | H12: =IF(A12="","",G12*D12/12) | I12: =IF(OR(A12="",N(G12)<=0),"",COUNTIF($N$9:$N$23,">"&N12)+COUNTIF($N$9:N12,N12)) | J12: =IF(I12="",0,O12+MIN(P12,MAX(0,$C$6-SUMIF($I$9:$I$23,"<"&I12,$P$9:$P$23)))) | K12: =IF(A12="","",IF(N(G12)<=0,0,IF(J12<=0,"Después de las anteriores",IF(D12=0,ROUNDUP(G12/J12,0),IF(J12<=H12,"Nunca: pago < interés",ROUNDUP(NPER(D12/12,-J12,G12),0)))))) | L12: =IF(ISNUMBER(K12),EDATE(Mes_Analisis,K12),"") | M12: =IF(A12="","",IF(N(G12)<=0,"✅ ¡Liquidada! Celébralo",IF(I12=1,"🎯 Ataca aquí: todo el dinero extra",IF(D12>0,"Paga el mínimo: genera intereses","Sin intereses: en segundo plano")))) | N12: =IF(A12="","",IF(G12<=0,-1,IF(D12>0,1+D12,1/(1+G12)))) | O12: =IF(OR(A12="",N(G12)<=0),0,MIN(G12,E12)) | P12: =IF(OR(A12="",N(G12)<=0),0,G12-O12)
A13: Préstamo hermano | B13: Préstamo familiar | C13: 4000 | D13: 0 | E13: 500 | F13: =IF(A13="",0,SUMIF('Abonos a Deudas'!$B$5:$B$304,A13,'Abonos a Deudas'!$C$5:$C$304)) | G13: =IF(A13="","",MAX(0,C13-F13)) | H13: =IF(A13="","",G13*D13/12) | I13: =IF(OR(A13="",N(G13)<=0),"",COUNTIF($N$9:$N$23,">"&N13)+COUNTIF($N$9:N13,N13)) | J13: =IF(I13="",0,O13+MIN(P13,MAX(0,$C$6-SUMIF($I$9:$I$23,"<"&I13,$P$9:$P$23)))) | K13: =IF(A13="","",IF(N(G13)<=0,0,IF(J13<=0,"Después de las anteriores",IF(D13=0,ROUNDUP(G13/J13,0),IF(J13<=H13,"Nunca: pago < interés",ROUNDUP(NPER(D13/12,-J13,G13),0)))))) | L13: =IF(ISNUMBER(K13),EDATE(Mes_Analisis,K13),"") | M13: =IF(A13="","",IF(N(G13)<=0,"✅ ¡Liquidada! Celébralo",IF(I13=1,"🎯 Ataca aquí: todo el dinero extra",IF(D13>0,"Paga el mínimo: genera intereses","Sin intereses: en segundo plano")))) | N13: =IF(A13="","",IF(G13<=0,-1,IF(D13>0,1+D13,1/(1+G13)))) | O13: =IF(OR(A13="",N(G13)<=0),0,MIN(G13,E13)) | P13: =IF(OR(A13="",N(G13)<=0),0,G13-O13)
F14: =IF(A14="",0,SUMIF('Abonos a Deudas'!$B$5:$B$304,A14,'Abonos a Deudas'!$C$5:$C$304)) | G14: =IF(A14="","",MAX(0,C14-F14)) | H14: =IF(A14="","",G14*D14/12) | I14: =IF(OR(A14="",N(G14)<=0),"",COUNTIF($N$9:$N$23,">"&N14)+COUNTIF($N$9:N14,N14)) | J14: =IF(I14="",0,O14+MIN(P14,MAX(0,$C$6-SUMIF($I$9:$I$23,"<"&I14,$P$9:$P$23)))) | K14: =IF(A14="","",IF(N(G14)<=0,0,IF(J14<=0,"Después de las anteriores",IF(D14=0,ROUNDUP(G14/J14,0),IF(J14<=H14,"Nunca: pago < interés",ROUNDUP(NPER(D14/12,-J14,G14),0)))))) | L14: =IF(ISNUMBER(K14),EDATE(Mes_Analisis,K14),"") | M14: =IF(A14="","",IF(N(G14)<=0,"✅ ¡Liquidada! Celébralo",IF(I14=1,"🎯 Ataca aquí: todo el dinero extra",IF(D14>0,"Paga el mínimo: genera intereses","Sin intereses: en segundo plano")))) | N14: =IF(A14="","",IF(G14<=0,-1,IF(D14>0,1+D14,1/(1+G14)))) | O14: =IF(OR(A14="",N(G14)<=0),0,MIN(G14,E14)) | P14: =IF(OR(A14="",N(G14)<=0),0,G14-O14)
F15: =IF(A15="",0,SUMIF('Abonos a Deudas'!$B$5:$B$304,A15,'Abonos a Deudas'!$C$5:$C$304)) | G15: =IF(A15="","",MAX(0,C15-F15)) | H15: =IF(A15="","",G15*D15/12) | I15: =IF(OR(A15="",N(G15)<=0),"",COUNTIF($N$9:$N$23,">"&N15)+COUNTIF($N$9:N15,N15)) | J15: =IF(I15="",0,O15+MIN(P15,MAX(0,$C$6-SUMIF($I$9:$I$23,"<"&I15,$P$9:$P$23)))) | K15: =IF(A15="","",IF(N(G15)<=0,0,IF(J15<=0,"Después de las anteriores",IF(D15=0,ROUNDUP(G15/J15,0),IF(J15<=H15,"Nunca: pago < interés",ROUNDUP(NPER(D15/12,-J15,G15),0)))))) | L15: =IF(ISNUMBER(K15),EDATE(Mes_Analisis,K15),"") | M15: =IF(A15="","",IF(N(G15)<=0,"✅ ¡Liquidada! Celébralo",IF(I15=1,"🎯 Ataca aquí: todo el dinero extra",IF(D15>0,"Paga el mínimo: genera intereses","Sin intereses: en segundo plano")))) | N15: =IF(A15="","",IF(G15<=0,-1,IF(D15>0,1+D15,1/(1+G15)))) | O15: =IF(OR(A15="",N(G15)<=0),0,MIN(G15,E15)) | P15: =IF(OR(A15="",N(G15)<=0),0,G15-O15)
F16: =IF(A16="",0,SUMIF('Abonos a Deudas'!$B$5:$B$304,A16,'Abonos a Deudas'!$C$5:$C$304)) | G16: =IF(A16="","",MAX(0,C16-F16)) | H16: =IF(A16="","",G16*D16/12) | I16: =IF(OR(A16="",N(G16)<=0),"",COUNTIF($N$9:$N$23,">"&N16)+COUNTIF($N$9:N16,N16)) | J16: =IF(I16="",0,O16+MIN(P16,MAX(0,$C$6-SUMIF($I$9:$I$23,"<"&I16,$P$9:$P$23)))) | K16: =IF(A16="","",IF(N(G16)<=0,0,IF(J16<=0,"Después de las anteriores",IF(D16=0,ROUNDUP(G16/J16,0),IF(J16<=H16,"Nunca: pago < interés",ROUNDUP(NPER(D16/12,-J16,G16),0)))))) | L16: =IF(ISNUMBER(K16),EDATE(Mes_Analisis,K16),"") | M16: =IF(A16="","",IF(N(G16)<=0,"✅ ¡Liquidada! Celébralo",IF(I16=1,"🎯 Ataca aquí: todo el dinero extra",IF(D16>0,"Paga el mínimo: genera intereses","Sin intereses: en segundo plano")))) | N16: =IF(A16="","",IF(G16<=0,-1,IF(D16>0,1+D16,1/(1+G16)))) | O16: =IF(OR(A16="",N(G16)<=0),0,MIN(G16,E16)) | P16: =IF(OR(A16="",N(G16)<=0),0,G16-O16)
F17: =IF(A17="",0,SUMIF('Abonos a Deudas'!$B$5:$B$304,A17,'Abonos a Deudas'!$C$5:$C$304)) | G17: =IF(A17="","",MAX(0,C17-F17)) | H17: =IF(A17="","",G17*D17/12) | I17: =IF(OR(A17="",N(G17)<=0),"",COUNTIF($N$9:$N$23,">"&N17)+COUNTIF($N$9:N17,N17)) | J17: =IF(I17="",0,O17+MIN(P17,MAX(0,$C$6-SUMIF($I$9:$I$23,"<"&I17,$P$9:$P$23)))) | K17: =IF(A17="","",IF(N(G17)<=0,0,IF(J17<=0,"Después de las anteriores",IF(D17=0,ROUNDUP(G17/J17,0),IF(J17<=H17,"Nunca: pago < interés",ROUNDUP(NPER(D17/12,-J17,G17),0)))))) | L17: =IF(ISNUMBER(K17),EDATE(Mes_Analisis,K17),"") | M17: =IF(A17="","",IF(N(G17)<=0,"✅ ¡Liquidada! Celébralo",IF(I17=1,"🎯 Ataca aquí: todo el dinero extra",IF(D17>0,"Paga el mínimo: genera intereses","Sin intereses: en segundo plano")))) | N17: =IF(A17="","",IF(G17<=0,-1,IF(D17>0,1+D17,1/(1+G17)))) | O17: =IF(OR(A17="",N(G17)<=0),0,MIN(G17,E17)) | P17: =IF(OR(A17="",N(G17)<=0),0,G17-O17)
F18: =IF(A18="",0,SUMIF('Abonos a Deudas'!$B$5:$B$304,A18,'Abonos a Deudas'!$C$5:$C$304)) | G18: =IF(A18="","",MAX(0,C18-F18)) | H18: =IF(A18="","",G18*D18/12) | I18: =IF(OR(A18="",N(G18)<=0),"",COUNTIF($N$9:$N$23,">"&N18)+COUNTIF($N$9:N18,N18)) | J18: =IF(I18="",0,O18+MIN(P18,MAX(0,$C$6-SUMIF($I$9:$I$23,"<"&I18,$P$9:$P$23)))) | K18: =IF(A18="","",IF(N(G18)<=0,0,IF(J18<=0,"Después de las anteriores",IF(D18=0,ROUNDUP(G18/J18,0),IF(J18<=H18,"Nunca: pago < interés",ROUNDUP(NPER(D18/12,-J18,G18),0)))))) | L18: =IF(ISNUMBER(K18),EDATE(Mes_Analisis,K18),"") | M18: =IF(A18="","",IF(N(G18)<=0,"✅ ¡Liquidada! Celébralo",IF(I18=1,"🎯 Ataca aquí: todo el dinero extra",IF(D18>0,"Paga el mínimo: genera intereses","Sin intereses: en segundo plano")))) | N18: =IF(A18="","",IF(G18<=0,-1,IF(D18>0,1+D18,1/(1+G18)))) | O18: =IF(OR(A18="",N(G18)<=0),0,MIN(G18,E18)) | P18: =IF(OR(A18="",N(G18)<=0),0,G18-O18)
F19: =IF(A19="",0,SUMIF('Abonos a Deudas'!$B$5:$B$304,A19,'Abonos a Deudas'!$C$5:$C$304)) | G19: =IF(A19="","",MAX(0,C19-F19)) | H19: =IF(A19="","",G19*D19/12) | I19: =IF(OR(A19="",N(G19)<=0),"",COUNTIF($N$9:$N$23,">"&N19)+COUNTIF($N$9:N19,N19)) | J19: =IF(I19="",0,O19+MIN(P19,MAX(0,$C$6-SUMIF($I$9:$I$23,"<"&I19,$P$9:$P$23)))) | K19: =IF(A19="","",IF(N(G19)<=0,0,IF(J19<=0,"Después de las anteriores",IF(D19=0,ROUNDUP(G19/J19,0),IF(J19<=H19,"Nunca: pago < interés",ROUNDUP(NPER(D19/12,-J19,G19),0)))))) | L19: =IF(ISNUMBER(K19),EDATE(Mes_Analisis,K19),"") | M19: =IF(A19="","",IF(N(G19)<=0,"✅ ¡Liquidada! Celébralo",IF(I19=1,"🎯 Ataca aquí: todo el dinero extra",IF(D19>0,"Paga el mínimo: genera intereses","Sin intereses: en segundo plano")))) | N19: =IF(A19="","",IF(G19<=0,-1,IF(D19>0,1+D19,1/(1+G19)))) | O19: =IF(OR(A19="",N(G19)<=0),0,MIN(G19,E19)) | P19: =IF(OR(A19="",N(G19)<=0),0,G19-O19)
F20: =IF(A20="",0,SUMIF('Abonos a Deudas'!$B$5:$B$304,A20,'Abonos a Deudas'!$C$5:$C$304)) | G20: =IF(A20="","",MAX(0,C20-F20)) | H20: =IF(A20="","",G20*D20/12) | I20: =IF(OR(A20="",N(G20)<=0),"",COUNTIF($N$9:$N$23,">"&N20)+COUNTIF($N$9:N20,N20)) | J20: =IF(I20="",0,O20+MIN(P20,MAX(0,$C$6-SUMIF($I$9:$I$23,"<"&I20,$P$9:$P$23)))) | K20: =IF(A20="","",IF(N(G20)<=0,0,IF(J20<=0,"Después de las anteriores",IF(D20=0,ROUNDUP(G20/J20,0),IF(J20<=H20,"Nunca: pago < interés",ROUNDUP(NPER(D20/12,-J20,G20),0)))))) | L20: =IF(ISNUMBER(K20),EDATE(Mes_Analisis,K20),"") | M20: =IF(A20="","",IF(N(G20)<=0,"✅ ¡Liquidada! Celébralo",IF(I20=1,"🎯 Ataca aquí: todo el dinero extra",IF(D20>0,"Paga el mínimo: genera intereses","Sin intereses: en segundo plano")))) | N20: =IF(A20="","",IF(G20<=0,-1,IF(D20>0,1+D20,1/(1+G20)))) | O20: =IF(OR(A20="",N(G20)<=0),0,MIN(G20,E20)) | P20: =IF(OR(A20="",N(G20)<=0),0,G20-O20)
F21: =IF(A21="",0,SUMIF('Abonos a Deudas'!$B$5:$B$304,A21,'Abonos a Deudas'!$C$5:$C$304)) | G21: =IF(A21="","",MAX(0,C21-F21)) | H21: =IF(A21="","",G21*D21/12) | I21: =IF(OR(A21="",N(G21)<=0),"",COUNTIF($N$9:$N$23,">"&N21)+COUNTIF($N$9:N21,N21)) | J21: =IF(I21="",0,O21+MIN(P21,MAX(0,$C$6-SUMIF($I$9:$I$23,"<"&I21,$P$9:$P$23)))) | K21: =IF(A21="","",IF(N(G21)<=0,0,IF(J21<=0,"Después de las anteriores",IF(D21=0,ROUNDUP(G21/J21,0),IF(J21<=H21,"Nunca: pago < interés",ROUNDUP(NPER(D21/12,-J21,G21),0)))))) | L21: =IF(ISNUMBER(K21),EDATE(Mes_Analisis,K21),"") | M21: =IF(A21="","",IF(N(G21)<=0,"✅ ¡Liquidada! Celébralo",IF(I21=1,"🎯 Ataca aquí: todo el dinero extra",IF(D21>0,"Paga el mínimo: genera intereses","Sin intereses: en segundo plano")))) | N21: =IF(A21="","",IF(G21<=0,-1,IF(D21>0,1+D21,1/(1+G21)))) | O21: =IF(OR(A21="",N(G21)<=0),0,MIN(G21,E21)) | P21: =IF(OR(A21="",N(G21)<=0),0,G21-O21)
F22: =IF(A22="",0,SUMIF('Abonos a Deudas'!$B$5:$B$304,A22,'Abonos a Deudas'!$C$5:$C$304)) | G22: =IF(A22="","",MAX(0,C22-F22)) | H22: =IF(A22="","",G22*D22/12) | I22: =IF(OR(A22="",N(G22)<=0),"",COUNTIF($N$9:$N$23,">"&N22)+COUNTIF($N$9:N22,N22)) | J22: =IF(I22="",0,O22+MIN(P22,MAX(0,$C$6-SUMIF($I$9:$I$23,"<"&I22,$P$9:$P$23)))) | K22: =IF(A22="","",IF(N(G22)<=0,0,IF(J22<=0,"Después de las anteriores",IF(D22=0,ROUNDUP(G22/J22,0),IF(J22<=H22,"Nunca: pago < interés",ROUNDUP(NPER(D22/12,-J22,G22),0)))))) | L22: =IF(ISNUMBER(K22),EDATE(Mes_Analisis,K22),"") | M22: =IF(A22="","",IF(N(G22)<=0,"✅ ¡Liquidada! Celébralo",IF(I22=1,"🎯 Ataca aquí: todo el dinero extra",IF(D22>0,"Paga el mínimo: genera intereses","Sin intereses: en segundo plano")))) | N22: =IF(A22="","",IF(G22<=0,-1,IF(D22>0,1+D22,1/(1+G22)))) | O22: =IF(OR(A22="",N(G22)<=0),0,MIN(G22,E22)) | P22: =IF(OR(A22="",N(G22)<=0),0,G22-O22)
F23: =IF(A23="",0,SUMIF('Abonos a Deudas'!$B$5:$B$304,A23,'Abonos a Deudas'!$C$5:$C$304)) | G23: =IF(A23="","",MAX(0,C23-F23)) | H23: =IF(A23="","",G23*D23/12) | I23: =IF(OR(A23="",N(G23)<=0),"",COUNTIF($N$9:$N$23,">"&N23)+COUNTIF($N$9:N23,N23)) | J23: =IF(I23="",0,O23+MIN(P23,MAX(0,$C$6-SUMIF($I$9:$I$23,"<"&I23,$P$9:$P$23)))) | K23: =IF(A23="","",IF(N(G23)<=0,0,IF(J23<=0,"Después de las anteriores",IF(D23=0,ROUNDUP(G23/J23,0),IF(J23<=H23,"Nunca: pago < interés",ROUNDUP(NPER(D23/12,-J23,G23),0)))))) | L23: =IF(ISNUMBER(K23),EDATE(Mes_Analisis,K23),"") | M23: =IF(A23="","",IF(N(G23)<=0,"✅ ¡Liquidada! Celébralo",IF(I23=1,"🎯 Ataca aquí: todo el dinero extra",IF(D23>0,"Paga el mínimo: genera intereses","Sin intereses: en segundo plano")))) | N23: =IF(A23="","",IF(G23<=0,-1,IF(D23>0,1+D23,1/(1+G23)))) | O23: =IF(OR(A23="",N(G23)<=0),0,MIN(G23,E23)) | P23: =IF(OR(A23="",N(G23)<=0),0,G23-O23)
A24: TOTAL | C24: =SUM(C9:C23) | E24: =SUM(E9:E23) | F24: =SUM(F9:F23) | G24: =SUM(G9:G23) | H24: =SUM(H9:H23) | J24: =SUM(J9:J23) | K24: =IF(COUNT(L9:L23)=0,"",MAX(L9:L23)) | M24: ← Libre de deudas (estimado)
A26: Cómo funciona
A27: • Cada mes cubres el pago mínimo de TODAS tus deudas para proteger tu historial.
A28: • Todo el dinero extra va a la deuda con prioridad 1. Al liquidarla, su pago pasa a la siguiente (efecto avalancha).
A29: • Las deudas con intereses van primero, de la tasa más alta a la más baja: cada peso ahí te ahorra más intereses.
A30: • Los préstamos familiares sin intereses van después, del saldo más pequeño al más grande, para liquidarlos uno a uno.
A31: • 'Meses para liquidar' y 'Fecha estimada libre' suponen que repites el pago sugerido de este mes; al acelerar con el efecto avalancha terminarás antes.

Sheet Abonos a Deudas
A1: ABONOS A DEUDAS
A2: Registra cada pago. El saldo de la deuda se actualiza solo en la hoja Deudas.
A4: Fecha | B4: Deuda | C4: Monto | D4: Nota | E4: Mes
A5: 46270 | B5: TDC Tienda departamental | C5: 3150 | D5: Mínimo + extra (prioridad 1) | E5: =IF(A5="","",DATE(YEAR(A5),MONTH(A5),1))
A6: 46270 | B6: TDC Banco Azul | C6: 1200 | D6: Pago mínimo | E6: =IF(A6="","",DATE(YEAR(A6),MONTH(A6),1))
A7: 46275 | B7: Préstamo personal | C7: 1500 | D7: Mensualidad | E7: =IF(A7="","",DATE(YEAR(A7),MONTH(A7),1))
A8: 46280 | B8: Préstamo hermano | C8: 500 | D8: Abono acordado | E8: =IF(A8="","",DATE(YEAR(A8),MONTH(A8),1))
E9: =IF(A9="","",DATE(YEAR(A9),MONTH(A9),1))
E10: =IF(A10="","",DATE(YEAR(A10),MONTH(A10),1))
E11: =IF(A11="","",DATE(YEAR(A11),MONTH(A11),1))
E12: =IF(A12="","",DATE(YEAR(A12),MONTH(A12),1))
E13: =IF(A13="","",DATE(YEAR(A13),MONTH(A13),1))
E14: =IF(A14="","",DATE(YEAR(A14),MONTH(A14),1))
E15: =IF(A15="","",DATE(YEAR(A15),MONTH(A15),1))
E16: =IF(A16="","",DATE(YEAR(A16),MONTH(A16),1))
E17: =IF(A17="","",DATE(YEAR(A17),MONTH(A17),1))
E18: =IF(A18="","",DATE(YEAR(A18),MONTH(A18),1))
E19: =IF(A19="","",DATE(YEAR(A19),MONTH(A19),1))
E20: =IF(A20="","",DATE(YEAR(A20),MONTH(A20),1))
... E304: =IF(A304="","",DATE(YEAR(A304),MONTH(A304),1))

Sheet Ahorro e Inversión
A1: AHORRO E INVERSIÓN · PÁGATE PRIMERO
A2: 'Una parte de todo lo que ganas es tuya para conservarla.' Registra aquí cada peso que pones a trabajar.
A4: Fecha | B4: Destino | C4: Monto | D4: Nota | E4: Mes
A5: 46266 | B5: Fondo de emergencia | C5: 1500 | D5: 10% de la quincena | E5: =IF(A5="","",DATE(YEAR(A5),MONTH(A5),1))
A6: 46280 | B6: Inversión (bolsa, CETES, fondos) | C6: 1000 | D6: CETES 28 días | E6: =IF(A6="","",DATE(YEAR(A6),MONTH(A6),1))
A7: 46285 | B7: Educación financiera | C7: 250 | D7: Libro / curso | E7: =IF(A7="","",DATE(YEAR(A7),MONTH(A7),1))
E8: =IF(A8="","",DATE(YEAR(A8),MONTH(A8),1))
E9: =IF(A9="","",DATE(YEAR(A9),MONTH(A9),1))
E10: =IF(A10="","",DATE(YEAR(A10),MONTH(A10),1))
E11: =IF(A11="","",DATE(YEAR(A11),MONTH(A11),1))
E12: =IF(A12="","",DATE(YEAR(A12),MONTH(A12),1))
E13: =IF(A13="","",DATE(YEAR(A13),MONTH(A13),1))
E14: =IF(A14="","",DATE(YEAR(A14),MONTH(A14),1))
E15: =IF(A15="","",DATE(YEAR(A15),MONTH(A15),1))
E16: =IF(A16="","",DATE(YEAR(A16),MONTH(A16),1))
E17: =IF(A17="","",DATE(YEAR(A17),MONTH(A17),1))
E18: =IF(A18="","",DATE(YEAR(A18),MONTH(A18),1))
E19: =IF(A19="","",DATE(YEAR(A19),MONTH(A19),1))
... E304: =IF(A304="","",DATE(YEAR(A304),MONTH(A304),1))

Sheet Tendencia
A1: ="TENDENCIA "&YEAR(Mes_Analisis)
A4: Mes | B4: Ingresos | C4: Gastos de vida | D4: Abonos a deudas | E4: Ahorro e inversión | F4: Disponible | G4: Ingreso pasivo | H4: Tasa de ahorro | I4: Índice libertad
A5: =DATE(YEAR(Mes_Analisis),1,1) | B5: =SUMIFS(Ingresos!$D$5:$D$304,Ingresos!$E$5:$E$304,A5) | C5: =SUMIFS(Gastos!$D$5:$D$1004,Gastos!$H$5:$H$1004,A5) | D5: =SUMIFS('Abonos a Deudas'!$C$5:$C$304,'Abonos a Deudas'!$E$5:$E$304,A5) | E5: =SUMIFS('Ahorro e Inversión'!$C$5:$C$304,'Ahorro e Inversión'!$E$5:$E$304,A5) | F5: =B5-C5-D5-E5 | G5: =SUMIFS(Ingresos!$D$5:$D$304,Ingresos!$E$5:$E$304,A5,Ingresos!$B$5:$B$304,"Ingreso pasivo") | H5: =IF(B5=0,0,E5/B5) | I5: =IF(C5=0,0,G5/C5)
A6: =DATE(YEAR(Mes_Analisis),2,1) | B6: =SUMIFS(Ingresos!$D$5:$D$304,Ingresos!$E$5:$E$304,A6) | C6: =SUMIFS(Gastos!$D$5:$D$1004,Gastos!$H$5:$H$1004,A6) | D6: =SUMIFS('Abonos a Deudas'!$C$5:$C$304,'Abonos a Deudas'!$E$5:$E$304,A6) | E6: =SUMIFS('Ahorro e Inversión'!$C$5:$C$304,'Ahorro e Inversión'!$E$5:$E$304,A6) | F6: =B6-C6-D6-E6 | G6: =SUMIFS(Ingresos!$D$5:$D$304,Ingresos!$E$5:$E$304,A6,Ingresos!$B$5:$B$304,"Ingreso pasivo") | H6: =IF(B6=0,0,E6/B6) | I6: =IF(C6=0,0,G6/C6)
A7: =DATE(YEAR(Mes_Analisis),3,1) | B7: =SUMIFS(Ingresos!$D$5:$D$304,Ingresos!$E$5:$E$304,A7) | C7: =SUMIFS(Gastos!$D$5:$D$1004,Gastos!$H$5:$H$1004,A7) | D7: =SUMIFS('Abonos a Deudas'!$C$5:$C$304,'Abonos a Deudas'!$E$5:$E$304,A7) | E7: =SUMIFS('Ahorro e Inversión'!$C$5:$C$304,'Ahorro e Inversión'!$E$5:$E$304,A7) | F7: =B7-C7-D7-E7 | G7: =SUMIFS(Ingresos!$D$5:$D$304,Ingresos!$E$5:$E$304,A7,Ingresos!$B$5:$B$304,"Ingreso pasivo") | H7: =IF(B7=0,0,E7/B7) | I7: =IF(C7=0,0,G7/C7)
A8: =DATE(YEAR(Mes_Analisis),4,1) | B8: =SUMIFS(Ingresos!$D$5:$D$304,Ingresos!$E$5:$E$304,A8) | C8: =SUMIFS(Gastos!$D$5:$D$1004,Gastos!$H$5:$H$1004,A8) | D8: =SUMIFS('Abonos a Deudas'!$C$5:$C$304,'Abonos a Deudas'!$E$5:$E$304,A8) | E8: =SUMIFS('Ahorro e Inversión'!$C$5:$C$304,'Ahorro e Inversión'!$E$5:$E$304,A8) | F8: =B8-C8-D8-E8 | G8: =SUMIFS(Ingresos!$D$5:$D$304,Ingresos!$E$5:$E$304,A8,Ingresos!$B$5:$B$304,"Ingreso pasivo") | H8: =IF(B8=0,0,E8/B8) | I8: =IF(C8=0,0,G8/C8)
A9: =DATE(YEAR(Mes_Analisis),5,1) | B9: =SUMIFS(Ingresos!$D$5:$D$304,Ingresos!$E$5:$E$304,A9) | C9: =SUMIFS(Gastos!$D$5:$D$1004,Gastos!$H$5:$H$1004,A9) | D9: =SUMIFS('Abonos a Deudas'!$C$5:$C$304,'Abonos a Deudas'!$E$5:$E$304,A9) | E9: =SUMIFS('Ahorro e Inversión'!$C$5:$C$304,'Ahorro e Inversión'!$E$5:$E$304,A9) | F9: =B9-C9-D9-E9 | G9: =SUMIFS(Ingresos!$D$5:$D$304,Ingresos!$E$5:$E$304,A9,Ingresos!$B$5:$B$304,"Ingreso pasivo") | H9: =IF(B9=0,0,E9/B9) | I9: =IF(C9=0,0,G9/C9)
A10: =DATE(YEAR(Mes_Analisis),6,1) | B10: =SUMIFS(Ingresos!$D$5:$D$304,Ingresos!$E$5:$E$304,A10) | C10: =SUMIFS(Gastos!$D$5:$D$1004,Gastos!$H$5:$H$1004,A10) | D10: =SUMIFS('Abonos a Deudas'!$C$5:$C$304,'Abonos a Deudas'!$E$5:$E$304,A10) | E10: =SUMIFS('Ahorro e Inversión'!$C$5:$C$304,'Ahorro e Inversión'!$E$5:$E$304,A10) | F10: =B10-C10-D10-E10 | G10: =SUMIFS(Ingresos!$D$5:$D$304,Ingresos!$E$5:$E$304,A10,Ingresos!$B$5:$B$304,"Ingreso pasivo") | H10: =IF(B10=0,0,E10/B10) | I10: =IF(C10=0,0,G10/C10)
A11: =DATE(YEAR(Mes_Analisis),7,1) | B11: =SUMIFS(Ingresos!$D$5:$D$304,Ingresos!$E$5:$E$304,A11) | C11: =SUMIFS(Gastos!$D$5:$D$1004,Gastos!$H$5:$H$1004,A11) | D11: =SUMIFS('Abonos a Deudas'!$C$5:$C$304,'Abonos a Deudas'!$E$5:$E$304,A11) | E11: =SUMIFS('Ahorro e Inversión'!$C$5:$C$304,'Ahorro e Inversión'!$E$5:$E$304,A11) | F11: =B11-C11-D11-E11 | G11: =SUMIFS(Ingresos!$D$5:$D$304,Ingresos!$E$5:$E$304,A11,Ingresos!$B$5:$B$304,"Ingreso pasivo") | H11: =IF(B11=0,0,E11/B11) | I11: =IF(C11=0,0,G11/C11)
A12: =DATE(YEAR(Mes_Analisis),8,1) | B12: =SUMIFS(Ingresos!$D$5:$D$304,Ingresos!$E$5:$E$304,A12) | C12: =SUMIFS(Gastos!$D$5:$D$1004,Gastos!$H$5:$H$1004,A12) | D12: =SUMIFS('Abonos a Deudas'!$C$5:$C$304,'Abonos a Deudas'!$E$5:$E$304,A12) | E12: =SUMIFS('Ahorro e Inversión'!$C$5:$C$304,'Ahorro e Inversión'!$E$5:$E$304,A12) | F12: =B12-C12-D12-E12 | G12: =SUMIFS(Ingresos!$D$5:$D$304,Ingresos!$E$5:$E$304,A12,Ingresos!$B$5:$B$304,"Ingreso pasivo") | H12: =IF(B12=0,0,E12/B12) | I12: =IF(C12=0,0,G12/C12)
A13: =DATE(YEAR(Mes_Analisis),9,1) | B13: =SUMIFS(Ingresos!$D$5:$D$304,Ingresos!$E$5:$E$304,A13) | C13: =SUMIFS(Gastos!$D$5:$D$1004,Gastos!$H$5:$H$1004,A13) | D13: =SUMIFS('Abonos a Deudas'!$C$5:$C$304,'Abonos a Deudas'!$E$5:$E$304,A13) | E13: =SUMIFS('Ahorro e Inversión'!$C$5:$C$304,'Ahorro e Inversión'!$E$5:$E$304,A13) | F13: =B13-C13-D13-E13 | G13: =SUMIFS(Ingresos!$D$5:$D$304,Ingresos!$E$5:$E$304,A13,Ingresos!$B$5:$B$304,"Ingreso pasivo") | H13: =IF(B13=0,0,E13/B13) | I13: =IF(C13=0,0,G13/C13)
A14: =DATE(YEAR(Mes_Analisis),10,1) | B14: =SUMIFS(Ingresos!$D$5:$D$304,Ingresos!$E$5:$E$304,A14) | C14: =SUMIFS(Gastos!$D$5:$D$1004,Gastos!$H$5:$H$1004,A14) | D14: =SUMIFS('Abonos a Deudas'!$C$5:$C$304,'Abonos a Deudas'!$E$5:$E$304,A14) | E14: =SUMIFS('Ahorro e Inversión'!$C$5:$C$304,'Ahorro e Inversión'!$E$5:$E$304,A14) | F14: =B14-C14-D14-E14 | G14: =SUMIFS(Ingresos!$D$5:$D$304,Ingresos!$E$5:$E$304,A14,Ingresos!$B$5:$B$304,"Ingreso pasivo") | H14: =IF(B14=0,0,E14/B14) | I14: =IF(C14=0,0,G14/C14)
A15: =DATE(YEAR(Mes_Analisis),11,1) | B15: =SUMIFS(Ingresos!$D$5:$D$304,Ingresos!$E$5:$E$304,A15) | C15: =SUMIFS(Gastos!$D$5:$D$1004,Gastos!$H$5:$H$1004,A15) | D15: =SUMIFS('Abonos a Deudas'!$C$5:$C$304,'Abonos a Deudas'!$E$5:$E$304,A15) | E15: =SUMIFS('Ahorro e Inversión'!$C$5:$C$304,'Ahorro e Inversión'!$E$5:$E$304,A15) | F15: =B15-C15-D15-E15 | G15: =SUMIFS(Ingresos!$D$5:$D$304,Ingresos!$E$5:$E$304,A15,Ingresos!$B$5:$B$304,"Ingreso pasivo") | H15: =IF(B15=0,0,E15/B15) | I15: =IF(C15=0,0,G15/C15)
A16: =DATE(YEAR(Mes_Analisis),12,1) | B16: =SUMIFS(Ingresos!$D$5:$D$304,Ingresos!$E$5:$E$304,A16) | C16: =SUMIFS(Gastos!$D$5:$D$1004,Gastos!$H$5:$H$1004,A16) | D16: =SUMIFS('Abonos a Deudas'!$C$5:$C$304,'Abonos a Deudas'!$E$5:$E$304,A16) | E16: =SUMIFS('Ahorro e Inversión'!$C$5:$C$304,'Ahorro e Inversión'!$E$5:$E$304,A16) | F16: =B16-C16-D16-E16 | G16: =SUMIFS(Ingresos!$D$5:$D$304,Ingresos!$E$5:$E$304,A16,Ingresos!$B$5:$B$304,"Ingreso pasivo") | H16: =IF(B16=0,0,E16/B16) | I16: =IF(C16=0,0,G16/C16)
A17: Total | B17: =SUM(B5:B16) | C17: =SUM(C5:C16) | D17: =SUM(D5:D16) | E17: =SUM(E5:E16) | F17: =SUM(F5:F16) | G17: =SUM(G5:G16) | H17: =IF(B17=0,0,E17/B17) | I17: =IF(C17=0,0,G17/C17)

Sheet Principios
A1: PRINCIPIOS QUE GUÍAN ESTA PLANTILLA
A2: Inspirados en 'El hombre más rico de Babilonia' (G. S. Clason) y 'Padre Rico, Padre Pobre' (R. Kiyosaki)
B4: Principio | C4: Cómo lo aplica tu plantilla
B5: Babilonia · 1ª cura: Empieza a engordar tu bolsa | C5: Págate primero: al menos 10% de cada ingreso va a Ahorro e Inversión ANTES de gastar.
B6: Babilonia · 2ª cura: Controla tus gastos | C6: Presupuesto por categoría y por periodo (día/semana) con semáforo. Distingue necesidades de deseos.
B7: Babilonia · 3ª cura: Haz que tu oro se multiplique | C7: El ahorro no se queda quieto: registra inversiones y el ingreso pasivo que generan.
B8: Babilonia · 4ª cura: Protege tus tesoros de la pérdida | C8: Fondo de emergencia con meta en meses de gastos antes de inversiones de riesgo.
B9: Babilonia · 5ª cura: Haz de tu vivienda una inversión rentable | C9: Categoría Vivienda con presupuesto; registra si tu vivienda te genera rentas.
B10: Babilonia · 6ª cura: Asegura un ingreso para el futuro | C10: Índice de libertad financiera: ingreso pasivo ÷ gastos de vida.
B11: Babilonia · 7ª cura: Aumenta tu habilidad para ganar | C11: Categoría 'Educación financiera' dentro de Ahorro e Inversión.
B12: Babilonia · Las deudas: 20% para pagarlas | C12: Regla de Arkad adaptada: 10% ahorro, 20% deudas, 70% para vivir. El plan de deudas usa ese 20%.
B13: Padre Rico · Los ricos compran activos | C13: Un activo pone dinero en tu bolsillo; un pasivo lo saca. Cada ingreso pasivo cuenta en tu tablero.
B14: Padre Rico · Págate a ti primero | C14: La columna 'Real' de ahorro se compara contra la meta del mes.
B15: Padre Rico · Aprende a leer tus números | C15: El Resumen es tu estado financiero personal: ingresos, gastos, activos y pasivos.
... B36: Hoy es el mejor día para empezar a engordar tu bolsa. | C36: El hombre más rico de Babilonia
B38: Frases parafraseadas de las obras citadas, con fines motivacionales.
